//
//  FutureRecoverTests.swift
//  FutureLib
//
//  Copyright Â© 2015 Andreas Grosam. All rights reserved.
//

import XCTest
import FutureLib


class FutureRecoverTests: XCTestCase {

    private let timeout: Foundation.TimeInterval = 1

    override func setUp() {
        super.setUp()
        // Put setup code here. This method is called before the invocation of each test method in the class.
    }

    override func tearDown() {
        // Put teardown code here. This method is called after the invocation of each test method in the class.
        super.tearDown()
    }

    // MARK: recover(_:)

    func testRecoverReturnsSuccesFutureWithPendingFuturePropagatesSuccessValueWhenCompletedWithSuccessValue() {
        let expect = self.expectation(description: "future should be completed")
        let asyncTask: ()-> Future<String> = {
            let promise = Promise<String>()
            schedule_after(0.001) {
                promise.fulfill("OK")
            }
            return promise.future!
        }
        asyncTask().recover { error in
            XCTFail("unexpected reecover")
            return "Failed"
        }
        .onSuccess { value in
            XCTAssertEqual("OK", value)
            expect.fulfill()
        }
        self.waitForExpectations(timeout: timeout, handler: nil)
    }


    func testRecoverReturnsSucceededFutureWithPendingFutureInvokesRecoverHandlerWhenCompletedWithError() {
        let expect1 = self.expectation(description: "future1 should be completed")
        let expect2 = self.expectation(description: "future2 should be completed")
        let asyncTask: ()-> Future<String> = {
            let promise = Promise<String>()
            schedule_after(0.001) {
                promise.reject(TestError.failed)
            }
            return promise.future!
        }
        asyncTask().recover { error in
            XCTAssertTrue(TestError.failed == error)
            expect1.fulfill()
            return "Failed"
        }
        .onSuccess { value in
            XCTAssertEqual("Failed", value)
            expect2.fulfill()
        }
        self.waitForExpectations(timeout: timeout, handler: nil)
    }


    func testRecoverReturnsFailedFutureWithPendingFutureInvokesRecoverHandlerWhichThrowsErrorWhenCompletedWithError() {
        let expect1 = self.expectation(description: "future1 should be completed")
        let expect2 = self.expectation(description: "future2 should be completed")
        let asyncTask: ()-> Future<String> = {
            let promise = Promise<String>()
            schedule_after(0.001) {
                promise.reject(TestError.failed)
            }
            return promise.future!
        }
        asyncTask().recover { error in
            XCTAssertTrue(TestError.failed == error)
            expect1.fulfill()
            throw TestError.failed
        }
        .onFailure { error in
            XCTAssertTrue(TestError.failed == error)
            expect2.fulfill()
        }
        self.waitForExpectations(timeout: timeout, handler: nil)
    }



    // MARK: recoeverWith(_:)

    func testRecoverWithReturnsSuccesFutureWithPendingFuturePropagatesSuccessValueWhenCompletedWithSuccessValue() {
        let expect = self.expectation(description: "future should be completed")
        let asyncTask: ()-> Future<String> = {
            let promise = Promise<String>()
            schedule_after(0.001) {
                promise.fulfill("OK")
            }
            return promise.future!
        }
        asyncTask().recoverWith { error in
            XCTFail("unexpected reecover")
            return Future<String>.succeededAfter(0.01, value: "Deferred Failed")
        }
        .onSuccess { value in
            XCTAssertEqual("OK", value)
            expect.fulfill()
        }
        self.waitForExpectations(timeout: timeout, handler: nil)
    }


    func testRecoverWithReturnsSucceededFutureWithPendingFutureInvokesRecoverHandlerWhenCompletedWithDeferredError() {
        let expect1 = self.expectation(description: "future1 should be completed")
        let expect2 = self.expectation(description: "future2 should be completed")
        let asyncTask: ()-> Future<String> = {
            let promise = Promise<String>()
            schedule_after(0.001) {
                promise.reject(TestError.failed)
            }
            return promise.future!
        }
        asyncTask().recoverWith { error in
            XCTAssertTrue(TestError.failed == error)
            expect1.fulfill()
            return Future<String>.succeededAfter(0.01, value: "Deferred Failed")
        }
        .onSuccess { value in
            XCTAssertEqual("Deferred Failed", value)
            expect2.fulfill()
        }
        self.waitForExpectations(timeout: timeout, handler: nil)
    }





}
